<?xml version="1.0"?>
<robot name="youbot_arm" >

	<!-- foot for arm -->
	<link name="base_link">
	</link>

	<!-- LINKS -->
	<link name="link_0">
		<visual>
			<origin xyz="0 0 0" rpy="0 0 0" />
			<geometry>
				<mesh filename="package://youbot_description/meshes/youbot_arm/arm0.dae" />
			</geometry>
			<material name="youBot/DarkGrey" />
		</visual>
		<collision>
			<origin xyz="0 0 0" rpy="0 0 0"/>
			<geometry>
				<mesh filename="package://youbot_description/meshes/youbot_arm/arm0_convex.dae" />
			</geometry>
		</collision>		
	</link>

	<link name="link_1">
		<visual>
			<origin xyz="0 0 0" rpy="0 0 0" />
			<geometry>
				<mesh filename="package://youbot_description/meshes/youbot_arm/arm1.dae" />
			</geometry>
			<material name="youBot/Orange" />
		</visual>
		<collision>
			<origin xyz="0 0 0" rpy="0 0 0" />
			<geometry>
				<mesh filename="package://youbot_description/meshes/youbot_arm/arm1_convex.dae" />
			</geometry>
		</collision>
	</link>

	<link name="link_2">
		<visual>
			<origin xyz="0 0.078 0.032" rpy="-1.57 0 0" />
			<geometry>
				<mesh filename="package://youbot_description/meshes/youbot_arm/arm2.dae" />
			</geometry>
		</visual>
		<collision>
			<origin xyz="0 -0.032 0.078" rpy="0 0 0" />
			<geometry>
				<mesh filename="package://youbot_description/meshes/youbot_arm/arm2_convex.dae" />
			</geometry>
		</collision>
	</link>

	<link name="link_3">
		<visual>
			<origin xyz="0.079 0 -0.028" rpy="-1.57 0 -1.57" />
			<geometry>
				<mesh filename="package://youbot_description/meshes/youbot_arm/arm3.dae" />
			</geometry>
			<material name="youBot/Orange" />
		</visual>
		<collision>
			<origin xyz="0.000 0.028 0.079" rpy="0 0 0" />
			<geometry>
				<mesh filename="package://youbot_description/meshes/youbot_arm/arm3_convex.dae" />
			</geometry>
		</collision>
	</link>

	<link name="link_4">
		<visual>
			<origin xyz="0 -0.029 0.010" rpy="-1.57 0 -3.1415"/>
			<geometry>
				<mesh filename="package://youbot_description/meshes/youbot_arm/arm4.dae" />
			</geometry>
			<material name="youBot/Orange" />
		</visual>
		<collision>
			<origin xyz="0 -0.010 0.029" rpy="0 0 0"/>
			<geometry>
				<mesh filename="package://youbot_description/meshes/youbot_arm/arm4_convex.dae" />
			</geometry>
		</collision>
	</link>

	<link name="link_5">
		<visual>
			<origin xyz="0 0 -0.017" rpy="0 0 3.1415" />
			<geometry>
				<mesh filename="package://youbot_description/meshes/youbot_arm/arm5.dae" />
			</geometry>
			<material name="youBot/DarkGrey" />
		</visual>
		<collision>
			<origin xyz="0.003 0 -0.034" rpy="0 0 0" />
			<geometry>
				<mesh filename="package://youbot_description/meshes/youbot_arm/arm5_convex.dae" />
			</geometry>
		</collision>		
	</link>

	<link name="palm_link">
		<visual>
			<origin xyz="-0.003 0 -0.042" rpy="0 0 0" />
			<geometry>
			<mesh filename="package://youbot_description/meshes/youbot_gripper/palm.dae" />
			</geometry>
			<material name="Black" />
		</visual>
		<collision>
			<origin xyz="0 0 0" rpy="0 0 0" />
			<geometry>
				<mesh filename="package://youbot_description/meshes/youbot_gripper/palm_convex.dae" />
			</geometry>
		</collision>		
	</link>

	<link name="finger_link_l">
		<visual>
			<origin xyz="0 0 0" rpy="0 0 0" />
			<geometry>
				<mesh filename="package://youbot_description/meshes/youbot_gripper/finger.dae" />
			</geometry>
			<material name="Black" />
		</visual>
		<collision>
			<origin xyz="0 0 0" rpy="0 0 0" />
			<geometry>
				<mesh filename="package://youbot_description/meshes/youbot_gripper/finger_convex.dae" />
			</geometry>
		</collision>		
	</link>

	<link name="finger_link_r">
		<visual>
			<origin xyz="0 0 0" rpy="0 0 3.1415" />
			<geometry>
				<mesh filename="package://youbot_description/meshes/youbot_gripper/finger.dae" />
			</geometry>
			<material name="Black" />
		</visual>
		<collision>
			<origin xyz="0.000 0 0" rpy="0 0 0" />
			<geometry>
				<mesh filename="package://youbot_description/meshes/youbot_gripper/finger_convex.dae" />
			</geometry>
		</collision>		
	</link>

	<!-- JOINTS -->
	<joint name="joint_0" type="fixed">
		<parent link="base_link"/>
		<child link="link_0"/>
        <limit effort="1000.0" lower="-3.1415" upper="3.1415" velocity="0.5"/>
        <origin xyz="0 0 0" rpy="0 0 0"/>
        <axis xyz="0 0 1"/>
	</joint>

	<joint name="joint_1" type="revolute">
		<parent link="link_0"/>
		<child link="link_1"/>
        <limit effort="1000.0" lower="-3.1415" upper="3.1415" velocity="0.5"/>
        <origin xyz="0.024 0 0.096" rpy="0 0 0"/>
        <axis xyz="0 0 1"/>
	</joint>

	<joint name="joint_2" type="revolute">
		<parent link="link_1"/>
		<child link="link_2"/>
		<limit effort="1000.0" lower="-3.1415" upper="3.1415" velocity="0.5"/>
		<origin xyz="0.033 0 0.019" rpy="1.57 0 0"/>
		<axis xyz="0 0 1"/>
	</joint>
	
	<joint name="joint_3" type="revolute">
		<parent link="link_2"/>
		<child link="link_3"/>
		<limit effort="1000.0" lower="-3.1415" upper="3.1415" velocity="0.5"/>
        <origin xyz="0 0.155 0" rpy="0 0 1.57"/> <!-- offset for Y ??? -->
        <axis xyz="0 0 1"/>
	</joint>
	
	<joint name="joint_4" type="revolute">
		<parent link="link_3"/>
		<child link="link_4"/>
		<limit effort="1000.0" lower="-3.1415" upper="3.1415" velocity="0.5"/>
		<origin xyz="0.135 0 0" rpy="0 0 0" />
		<axis xyz="0 0 1"/>
	</joint>
	
	<joint name="joint_5" type="revolute">
		<parent link="link_4"/>
		<child link="link_5"/>
		<limit effort="1000.0" lower="-3.1415" upper="3.1415" velocity="0.5"/>
		<origin xyz="0 -0.1136 0" rpy="1.57 0 0" />
		<axis xyz="0 0 1"/>
	</joint>
	
	<!-- palm from joint_5 to griper -->
	<joint name="base_gripper" type="fixed">
		<parent link="link_5"/>
		<child link="palm_link"/>
		<origin xyz="0 0 0.05716" rpy="0 0 0" />
	</joint>
	
	<joint name="finger_joint_l" type="prismatic">
		<parent link="palm_link"/>
		<child link="finger_link_l"/>
		<limit effort="1" velocity="0.1" lower="0" upper="0.0125"/> 
		<origin xyz="0 0.0082 0" rpy="0 0 3.141592" />
		<axis xyz="0 -1 0" />
	</joint>		

	<joint name="finger_joint_r" type="prismatic">
		<parent link="palm_link"/>
		<child link="finger_link_r"/>
		<limit effort="1" velocity="0.1" lower="-0.0125" upper="0"/> 
		<origin xyz="0 -0.0082 0" rpy="0 0 3.141592" />
		<axis xyz="0 -1 0"/> 
	</joint>		

</robot>